<!-- ======================================================
	Model 		:: 4W-Rover for Robot Trekking (2016)
		
	Mujoco		:: Advanced physics simulation engine
	Version		:: 0.2
====================================================== -->
<mujoco model="rover (v0.2)">

    <compiler inertiafromgeom="true" angle="degree"/>
	<option	timestep="0.02" gravity="0 0 -9.81"/>
	
	<asset>
		<material name="MatWheel" specular="1" rgba=".1 .1 .1 1"/>
		<material name="MatBody" specular="1" rgba=".6 .6 .1 1"/>
	</asset>
	
	<default>
		<geom contype="1" conaffinity="1"/>
	</default>
	
	<visual>
		<headlight active="1"/>
		<scale camera=".5"/>
		<map znear="0.001" zfar="1000"/>
	</visual>
	
    <worldbody>
		
		<body name="rover" pos="3 3 .5">
		
			<light name="lamp" active="true" directional="true" cutoff="4" exponent="20" diffuse="1 1 1" specular="0 0 0" pos="0 0 2.5" dir="0 0 -1 "/>
			
			<camera name="first-person" mode="fixed" pos=".22 0 .08" euler="180 -133 -90" fovy="90"/>
			
			<joint name="centroid" type="free" pos="0 0 0"/>
            <geom name="rover-body" type="box" pos="0 0 0" size="0.2 0.15 .095" mass="12" material="MatBody"/>
			<site type="box" size=".01 .07 .07" pos=".2 0 0"/>
            <body name="r-l-wheel" pos="-0.2 0.15 -0.15">
                <joint name="r-l-drive-hinge" type="hinge" pos="0 0 0" axis="0 1 0" damping="0.01" />
                <geom type="cylinder" size=".05" fromto="0 0 0 0 0.05 0" mass=".125" material="MatWheel" condim="4"/>
				<site size=".01" pos="0 .05 .03"/>
				<site size=".01" pos="0 .05 -.03"/>
				<site size=".01" pos="0 0 .03"/>
				<site size=".01" pos="0 0 -.03"/>
            </body>
            <body name="r-r-wheel" pos="-0.2 -0.15 -0.15">
                <joint name="r-r-drive-hinge" type="hinge" pos="0 0 0" axis="0 1 0" damping="0.01"/>
                <geom type="cylinder" size=".05" fromto="0 0 0 0 -0.05 0" mass=".125" material="MatWheel" condim="4"/>
				<site size=".01" pos="0 -.05 .03"/>
				<site size=".01" pos="0 -.05 -.03"/>
				<site size=".01" pos="0 0 .03"/>
				<site size=".01" pos="0 0 -.03"/>
            </body>
			<body name="steer-bar" pos=".2 0 -.15">
                <joint name="steer-hinge" type="hinge" pos="0 0 0" axis="0 0 1" range="-30 30" limited="true" damping="0.01"/>
				<geom type="capsule" size=".01 .15" quat="0.70710678118 0.70710678118 0 0" contype="2" conaffinity="2"/>
				<body name="f-l-wheel" pos="0 0.15 0">
					<joint name="f-l-drive-hinge" type="hinge" pos="0 0 0" axis="0 1 0" damping="0.01"/>
					<geom type="cylinder" size=".05" fromto="0 0 0 0 0.05 0" mass=".125" material="MatWheel" condim="4"/>
					<site size=".01" pos="0 .05 .03"/>
					<site size=".01" pos="0 .05 -.03"/>
					<site size=".01" pos="0 0 .03"/>
					<site size=".01" pos="0 0 -.03"/>
				</body>
				<body name="f-r-wheel" pos="0 -0.15 0">
					<joint name="f-r-drive-hinge" type="hinge" pos="0 0 0" axis="0 1 0" damping="0.01"/>
					<geom type="cylinder" size=".05" fromto="0 0 0 0 -0.05 0" mass=".125" material="MatWheel" condim="4"/>
					<site size=".01" pos="0 -.05 .03"/>
					<site size=".01" pos="0 -.05 -.03"/>
					<site size=".01" pos="0 0 .03"/>
					<site size=".01" pos="0 0 -.03"/>
				</body>
			</body>
			
			<body name="drive" pos="-0.2 0 -0.15">
				<joint name="drive-hinge" type="hinge" axis="0 1 0" damping="0.01"/>
				<geom type="box" size=".02 .04 .02"/>
			</body>
			
        </body>
    </worldbody>
	
	<tendon>
		<fixed name="rear-differential">
			<joint joint="r-l-drive-hinge" coef="1"/>
			<joint joint="r-r-drive-hinge" coef="1"/>
		</fixed>
	</tendon>
	
    <actuator>
        <motor name="steer-bar" joint="steer-hinge" ctrllimited="true" ctrlrange="-1.0 1.0" gear="1.0"/>
        <motor name="drive" tendon="rear-differential" ctrllimited="true" ctrlrange="-1.0 1.0" gear="1.5"/>
    </actuator>
	
	<!--equality>
		<joint name="r-drive-wheels" joint1="r-r-drive-hinge" joint2="drive-hinge" polycoef="0 1 0 0 0"/>
		<joint name="l-drive-wheels" joint1="r-l-drive-hinge" joint2="drive-hinge" polycoef="0 1 0 0 0"/>
	</equality-->
	
</mujoco>
