<!-- ======================================================
	Model 		:: 3W-Rover for Robot Trekking (2016)
		
	Mujoco		:: Advanced physics simulation engine
	Version		:: 0.2
====================================================== -->
<mujoco model="rover (v0.2)">

    <compiler inertiafromgeom="true" angle="degree"/>
	<option	timestep="0.02" gravity="0 0 -9.81"/>
	
	<asset>
		<material name="MatWheel" specular="1" rgba=".1 .1 .1 1"/>
		<material name="MatBody" specular="1" rgba=".6 .6 .1 1"/>
	</asset>
	
	<default>
		<geom contype="1" conaffinity="1"/>
	</default>
	
	<visual>
		<headlight active="1"/>
		<scale camera=".5"/>
		<map znear="0.001" zfar="1000"/>
	</visual>
	
    <worldbody>
		<body name="rover" pos="3 3 .5">
			<light directional="true" cutoff="4" exponent="1" diffuse="1 1 1" specular="0 0 0" pos="0 .3 2.5" dir="0 -.3 -2.5 "/>
			<camera name="first-person" mode="fixed" pos=".22 0 .08" euler="180 -133 -90" fovy="90"/>
        	<joint name="centroid" type="free" pos="0 0 0"/>
            <geom name="rover-body" type="box" pos="0 0 0" size="0.2 0.15 .05" mass="12" material="MatBody"/>
			<site type="box" size=".01 .07 .04" pos=".2 0 0"/>
            <body name="r-l-wheel" pos="-0.2 0.15 -0.115">
				<joint name="r-l-steer-hinge" type="hinge" pos="0 0 0" axis="0 0 1" limited="true" damping="0.01" range="-1 1"/>
                <joint name="r-l-drive-hinge" type="hinge" pos="0 0 0" axis="0 1 0" damping="0.01"/>
                <geom type="cylinder" size=".05" fromto="0 0 0 0 0.015 0" mass=".125" material="MatWheel" condim="4"/>
				<site size=".01" pos="0 .015 .03"/>
				<site size=".01" pos="0 .015 -.03"/>
				<site size=".01" pos="0 0 .03"/>
				<site size=".01" pos="0 0 -.03"/>
            </body>
            <body name="r-r-wheel" pos="-0.2 -0.15 -0.115">
				<joint name="r-r-steer-hinge" type="hinge" pos="0 0 0" axis="0 0 1" limited="true" damping="0.01" range="-1 1"/>
                <joint name="r-r-drive-hinge" type="hinge" pos="0 0 0" axis="0 1 0" damping="0.01"/>
                <geom type="cylinder" size=".05" fromto="0 0 0 0 -0.015 0" mass=".125" material="MatWheel" condim="4"/>
				<site size=".01" pos="0 -.015 .03"/>
				<site size=".01" pos="0 -.015 -.03"/>
				<site size=".01" pos="0 0 .03"/>
				<site size=".01" pos="0 0 -.03"/>
            </body>
			<body name="steer-l-wheel" pos=".2 0.15 -.115">
				<joint name="f-l-drive-hinge" type="hinge" pos="0.03 0 0" axis="0 0 1" damping="0.01"/>
                <joint name="steer-l-hinge" type="hinge" pos="0 0 0" axis="0 1 0" damping="0.01"/>
				<geom type="cylinder" size=".05" fromto="0 0 0 0 0.015 0" mass=".125" material="MatWheel" condim="4"/>
				<site type="box" size=".01 .015 .01" pos="0 0.0075 0"/>
            </body>
			<body name="steer-r-wheel" pos=".2 -0.15 -.115">
				<joint name="f-r-drive-hinge" type="hinge" pos="0.03 0 0" axis="0 0 1" damping="0.01"/>
                <joint name="steer-r-hinge" type="hinge" pos="0 0 0" axis="0 1 0" damping="0.01"/>
				<geom type="cylinder" size=".05" fromto="0 -0.015 0 0 0 0" mass=".125" material="MatWheel" condim="4"/>
				<site type="box" size=".01 .015 .01" pos="0 -0.0075 0"/>
            </body>
			<!--body name="steer-r-wheel" pos=".2 -0.15 -.115">
				<joint name="f-l-drive-hinge" type="hinge" pos="0.03 0 0" axis="0 0 1" damping="0.01"/>
                <joint name="steer-r-hinge" type="hinge" pos="0 0 0" axis="0 1 0" damping="0.01"/>
				<geom type="cylinder" size=".05" fromto="0 0 0 0 -0.015 0" mass=".125" material="MatWheel" condim="4"/>
				<site type="box" size=".01 .015 .01" pos="0 0 0"/>
            </body-->
		</body>
    </worldbody>
	
    <actuator>
        <motor name="r-l-wheel" joint="r-l-drive-hinge" ctrllimited="true" ctrlrange="-1.0 1.0" gear="0.75"/>
        <motor name="r-r-wheel" joint="r-r-drive-hinge" ctrllimited="true" ctrlrange="-1.0 1.0" gear="0.75"/>
    </actuator>
	
	<equality>
		<!--joint name="r-steer-bar" joint1="f-r-steer-hinge" joint2="rack-slide" polycoef="0 -1500 0 0 0"/-->
		<!--joint name="l-steer-bar" joint1="f-l-steer-hinge" joint2="rack-slide" polycoef="0 -1500 0 0 0"/-->
		<!--joint name="r-drive-wheels" joint1="r-r-drive-hinge" joint2="drive-hinge" polycoef="0 1 0 0 0"/-->
		<!--joint name="l-drive-wheels" joint1="r-l-drive-hinge" joint2="drive-hinge" polycoef="0 1 0 0 0"/-->
	</equality>
	
</mujoco>
